Workbook

Sheet Model
A1: Applied Elements: HPQ purification unit economics
A2: Amber cells are INPUTS. Everything else is a live Excel formula, so changing an ore or site selector recomputes the sheet. No calculated cell contains a pasted Python result.
A4: SELECTORS
A5: Ore | B5: Ore A, vein quartz, low Al | C5: Sets Al level, lot variability and stage yields
A6: Site | B6: Site 1, India, Telangana | C6: Sets power, reagent, labour and freight prices
A9: ORE TABLE (lookup source)
A10: name | B10: Al mean ppm | C10: Al lot sigma ppm | D10: flotation yield | E10: leach yield
A11: Ore A, vein quartz, low Al | B11: 18 | C11: 3 | D11: 0.85 | E11: 0.92
A12: Ore B, pegmatite, moderate Al | B12: 26 | C12: 5 | D12: 0.82 | E12: 0.9
A13: Ore C, high variability | B13: 22 | C13: 8 | D13: 0.8 | E13: 0.88
A15: SITE TABLE (lookup source)
A16: name | B16: power USD/kWh | C16: reagent USD/kg | D16: labour USD/h | E16: freight USD/t
A17: Site 1, India, Telangana | B17: 0.081 | C17: 1.8 | D17: 4.5 | E17: 95
A18: Site 2, US, low-cost power | B18: 0.0541 | C18: 2.4 | D18: 36.92 | E18: 25
A19: Site 3, US, average power | B19: 0.0889 | C19: 2.4 | D19: 36.92 | E19: 25
A22: RESOLVED DRIVERS (from selectors)
A23: Al mean, ppm | B23: =VLOOKUP($B$5,$A$11:$E$13,2,FALSE) -> 0
A24: Al lot sigma, ppm | B24: =VLOOKUP($B$5,$A$11:$E$13,3,FALSE) -> 0
A25: Flotation mass yield | B25: =VLOOKUP($B$5,$A$11:$E$13,4,FALSE) -> 0
A26: Leach mass yield | B26: =VLOOKUP($B$5,$A$11:$E$13,5,FALSE) -> 0
A27: Power price, USD/kWh | B27: =VLOOKUP($B$6,$A$17:$E$19,2,FALSE) -> 0
A28: Reagent price, USD/kg | B28: =VLOOKUP($B$6,$A$17:$E$19,3,FALSE) -> 0
A29: Labour, USD/h | B29: =VLOOKUP($B$6,$A$17:$E$19,4,FALSE) -> 0
A30: Freight, USD/t | B30: =VLOOKUP($B$6,$A$17:$E$19,5,FALSE) -> 0
A32: FIXED ASSUMPTIONS
A33: Al upper spec limit, ppm | B33: 30
A34: Feed, t/yr | B34: 7000
A35: Product price, USD/t | B35: 3500
A36: Power, kWh per t feed | B36: 250
A37: Reagent, kg per t feed | B37: 12
A38: Operators | B38: 24
A39: Operator hours per year | B39: 2000
A40: Maintenance, fraction of capex/yr | B40: 0.04
A41: Overhead, USD/yr | B41: 1800000
A42: Capex, MUSD | B42: 38
A43: Discount rate | B43: 0.14
A44: Life, years | B44: 10
A45: Tax rate | B45: 0.25
A47: CALCULATED (live formulas)
A48: Mass yield, cascade | B48: =$B$25*$B$26 -> 0 | C48: Stage yields multiply. Two 90 percent stages give 81 percent, not 90.
...

Sheet Reconciliation
A1: Reconciliation: Excel formulas against the Python model
A2: Column B is computed by this workbook's own formulas. Column C is the Python model's value for the SAME scenario, written at build time. Column D is the relative difference. A nonzero D means the workbook and the model have diverged, which is the condition this sheet exists to expose.
A4: quantity | B4: workbook formula | C4: Python model | D4: relative difference | E4: note
A5: Mass yield | B5: =Model!$B$48 -> 0 | C5: 0.782 | D5: =IF($C$5=0,ABS($B$5),ABS($B$5-$C$5)/ABS($C$5)) -> 0
A6: Off-spec fraction | B6: =Model!$B$49 -> 0 | C6: 0.00076526576 | D6: =IF($C$6=0,ABS($B$6),ABS($B$6-$C$6)/ABS($C$6)) -> 0
A7: Overall yield | B7: =Model!$B$51 -> 0 | C7: 0.78140156 | D7: =IF($C$7=0,ABS($B$7),ABS($B$7-$C$7)/ABS($C$7)) -> 0
A8: Product, t/yr | B8: =Model!$B$52 -> 0 | C8: 5469.8109 | D8: =IF($C$8=0,ABS($B$8),ABS($B$8-$C$8)/ABS($C$8)) -> 0
A9: Cash cost, USD/t | B9: =Model!$B$58 -> 0 | C9: 795.01505 | D9: =IF($C$9=0,ABS($B$9),ABS($B$9-$C$9)/ABS($C$9)) -> 0
A11: Worst relative difference | D11: =MAX($D$5:$D$9) -> 0
A12: Status | D12: =IF($D$11<0.000001,"RECONCILED","DIVERGED") -> 0
A14: NPV, IRR and breakeven are NOT reconciled here, and that is deliberate rather than an omission: the workbook computes them on a level annuity, while the Python model discounts an explicit per-period cash flow array with construction timing, ramp fractions and working capital. Those are different models, so forcing them to agree would mean degrading one. The workbook is for interrogating unit economics; the Python model is authoritative for valuation.

Sheet Scenario grid
A1: All ore and site combinations (Python model values)
A2: IMPORTED RESULTS, not live formulas: each row is the Python model evaluated at build time. The Model sheet is the live one. Reported so a reader can see the spread without switching selectors nine times.
A4: ore | B4: site | C4: mass yield | D4: off-spec | E4: overall yield | F4: product t/yr | G4: cash cost USD/t | H4: NPV MUSD | I4: IRR | J4: LCOP USD/t | K4: breakeven USD/t
A5: Ore A, vein quartz, low Al | B5: Site 1, India, Telangana | C5: 0.782 | D5: 0.00076526576 | E5: 0.78140156 | F5: 5469.8109 | G5: 795.01505 | H5: 24.837592 | I5: 0.29269167 | J5: 2126.8919 | K5: 2339.2767
A6: Ore A, vein quartz, low Al | B6: Site 2, US, low-cost power | C6: 0.782 | D6: 0.00076526576 | E6: 0.78140156 | F6: 5469.8109 | G6: 1010.1227 | H6: 20.234637 | I6: 0.26602609 | J6: 2341.9996 | K6: 2554.3844
A7: Ore A, vein quartz, low Al | B7: Site 3, US, average power | C7: 0.782 | D7: 0.00076526576 | E7: 0.78140156 | F7: 5469.8109 | G7: 1021.2566 | H7: 19.996391 | I7: 0.26463112 | J7: 2353.1334 | K7: 2565.5182
A8: Ore B, pegmatite, moderate Al | B8: Site 1, India, Telangana | C8: 0.738 | D8: 0.19871677 | E8: 0.59134702 | F8: 4139.4291 | G8: 1019.9947 | H8: 7.1160343 | I8: 0.18642359 | J8: 2779.9269 | K8: 3060.5706
A9: Ore B, pegmatite, moderate Al | B9: Site 2, US, low-cost power | C9: 0.738 | D9: 0.19871677 | E9: 0.59134702 | F9: 4139.4291 | G9: 1326.7338 | H9: 2.1487601 | I9: 0.15433455 | J9: 3086.666 | K9: 3367.3098
A10: Ore B, pegmatite, moderate Al | B10: Site 3, US, average power | C10: 0.738 | D10: 0.19871677 | E10: 0.59134702 | F10: 4139.4291 | G10: 1341.446 | H10: 1.9105141 | I10: 0.15275992 | J10: 3101.3782 | K10: 3382.0219
A11: Ore C, high variability | B11: Site 1, India, Telangana | C11: 0.704 | D11: 0.1454136 | E11: 0.60162883 | F11: 4211.4018 | G11: 1004.1866 | H11: 8.0747572 | I11: 0.19247012 | J11: 2734.0416 | K11: 3009.8891
A12: Ore C, high variability | B12: Site 2, US, low-cost power | C12: 0.704 | D12: 0.1454136 | E12: 0.60162883 | F12: 4211.4018 | G12: 1304.4873 | H12: 3.1271924 | I12: 0.1607648 | J12: 3034.3423 | K12: 3310.1898
A13: Ore C, high variability | B13: Site 3, US, average power | C13: 0.704 | D13: 0.1454136 | E13: 0.60162883 | F13: 4211.4018 | G13: 1318.948 | H13: 2.8889464 | I13: 0.15920436 | J13: 3048.803 | K13: 3324.6506

Sheet Provenance
A1: Where these numbers come from
A3: Built by | B3: scripts/build_workbook.py in the applied-elements repo
A4: Authoritative model | B4: the Python package; this workbook mirrors it
A5: Ore rows | B5: SCENARIO INPUTS, not measurements. No ore from the Vikarabad lease has been characterized, so no row here represents an assayed feedstock.
A6: Al spec limit | B6: 30 ppm, the HPQ-grade limit used throughout the platform
A7: Site power prices | B7: Telangana 33 kV HT-I(A) tariff and EIA Electric Power Monthly Table 5.6.B state averages
A8: Freight | B8: observed India-to-US CIF minus FOB on HS 250610, USD 76 to 115 per tonne
A9: Capex | B9: AACE Class 5, minus 50 to plus 100 percent. A factored estimate from an equipment list with no flowsheet engineering cannot claim better.
A10: Not in this workbook | B10: Monte Carlo and Sobol. Those need 10,000 draws and a variance decomposition, which is not honestly expressible in formulas.
A11: Parameter registry | B11: data/registry/parameter_registry.csv lists every tracked parameter with its tag, source and uncertainty
